<?xml version="1.0"?>
<!-- =================================================================================== -->
<!-- |    This document was autogenerated by xacro from ur5_dh.xacro                   | -->
<!-- |    EDITING THIS FILE BY HAND IS NOT RECOMMENDED                                 | -->
<!-- =================================================================================== -->
<robot name="UR5">
  <!-- Robot arm defination starts from here-->
  <!-- DH parameters are taken from this
  https://www.universal-robots.com/articles/ur/application-installation/dh-parameters-for-calculations-of-kinematics-and-dynamics/-->
  <link name="world" />
  <material name="mat_0">
    <color rgba="1 0 0 0.7" />
  </material>
  <link name="Link_0">
    <visual>
      <geometry>
        <cylinder length="0.089159" radius="0.05" />
      </geometry>
      <origin rpy="0 0 0" xyz="0  0 0.0445795" />
      <material name="mat_0" />
    </visual>
    <collision>
      <geometry>
        <cylinder length="0.089159" radius="0.05" />
      </geometry>
      <origin rpy="0 0 0" xyz="0  0 0.0445795" />
    </collision>
    <inertial>
      <mass value="1" />
      <inertia ixx="0.4" ixy="0.0" ixz="0.0" iyy="0.4" iyz="0.0" izz="0.2" />
    </inertial>
  </link>
  <joint name="Joint_0" type="revolute">
    <parent link="world" />
    <child link="Link_0" />
    <origin rpy="0 0 0" xyz="0 0.0 0" />
    <axis xyz="0 0 1" />
    <dynamics damping="0.0" friction="0.0" />
    <limit effort="10" lower="-10" upper="10" velocity="10" />
  </joint>
  <link name="Link_0_child_frame">
  </link>
  <joint name="0_child_frame_joint" type="fixed">
    <origin rpy="1.57079632679 0 0" xyz="0  0 0.089159" />
    <parent link="Link_0" />
    <child link="Link_0_child_frame" />
  </joint>
  <material name="mat_1">
    <color rgba="0 1 0 0.7" />
  </material>
  <link name="Link_1">
    <visual>
      <geometry>
        <cylinder length="0" radius="0.05" />
      </geometry>
      <origin rpy="0 0 0" xyz="0  0 0.0" />
      <material name="mat_1" />
    </visual>
    <visual>
      <geometry>
        <cylinder length="-0.425" radius="0.05" />
      </geometry>
      <origin rpy="0 1.57079632679 0" xyz="-0.2125  0 0" />
      <material name="mat_1" />
    </visual>
    <collision>
      <geometry>
        <cylinder length="0" radius="0.05" />
      </geometry>
      <origin rpy="0 0 0" xyz="0  0 0.0" />
    </collision>
    <collision>
      <geometry>
        <cylinder length="-0.425" radius="0.05" />
      </geometry>
      <origin rpy="0 1.57079632679 0" xyz="-0.2125  0 0" />
      <material name="mat_1" />
    </collision>
    <inertial>
      <mass value="1" />
      <inertia ixx="0.4" ixy="0.0" ixz="0.0" iyy="0.4" iyz="0.0" izz="0.2" />
    </inertial>
  </link>
  <joint name="Joint_1" type="revolute">
    <parent link="Link_0_child_frame" />
    <child link="Link_1" />
    <origin rpy="0 0 0" xyz="0 0.0 0" />
    <axis xyz="0 0 1" />
    <dynamics damping="0.0" friction="0.0" />
    <limit effort="10" lower="-10" upper="10" velocity="10" />
  </joint>
  <link name="Link_1_child_frame">
  </link>
  <joint name="1_child_frame_joint" type="fixed">
    <origin rpy="0 0 0" xyz="-0.425  0 0" />
    <parent link="Link_1" />
    <child link="Link_1_child_frame" />
  </joint>
  <material name="mat_2">
    <color rgba="0 0 1 0.7" />
  </material>
  <link name="Link_2">
    <visual>
      <geometry>
        <cylinder length="0" radius="0.05" />
      </geometry>
      <origin rpy="0 0 0" xyz="0  0 0.0" />
      <material name="mat_2" />
    </visual>
    <visual>
      <geometry>
        <cylinder length="-0.39225" radius="0.05" />
      </geometry>
      <origin rpy="0 1.57079632679 0" xyz="-0.196125  0 0" />
      <material name="mat_2" />
    </visual>
    <collision>
      <geometry>
        <cylinder length="0" radius="0.05" />
      </geometry>
      <origin rpy="0 0 0" xyz="0  0 0.0" />
    </collision>
    <collision>
      <geometry>
        <cylinder length="-0.39225" radius="0.05" />
      </geometry>
      <origin rpy="0 1.57079632679 0" xyz="-0.196125  0 0" />
      <material name="mat_2" />
    </collision>
    <inertial>
      <mass value="1" />
      <inertia ixx="0.4" ixy="0.0" ixz="0.0" iyy="0.4" iyz="0.0" izz="0.2" />
    </inertial>
  </link>
  <joint name="Joint_2" type="revolute">
    <parent link="Link_1_child_frame" />
    <child link="Link_2" />
    <origin rpy="0 0 0" xyz="0 0.0 0" />
    <axis xyz="0 0 1" />
    <dynamics damping="0.0" friction="0.0" />
    <limit effort="10" lower="-10" upper="10" velocity="10" />
  </joint>
  <link name="Link_2_child_frame">
  </link>
  <joint name="2_child_frame_joint" type="fixed">
    <origin rpy="0 0 0" xyz="-0.39225  0 0" />
    <parent link="Link_2" />
    <child link="Link_2_child_frame" />
  </joint>
  <material name="mat_3">
    <color rgba="0 1 1 0.7" />
  </material>
  <link name="Link_3">
    <visual>
      <geometry>
        <cylinder length="0.10915" radius="0.05" />
      </geometry>
      <origin rpy="0 0 0" xyz="0  0 0.054575" />
      <material name="mat_3" />
    </visual>
    <collision>
      <geometry>
        <cylinder length="0.10915" radius="0.05" />
      </geometry>
      <origin rpy="0 0 0" xyz="0  0 0.054575" />
    </collision>
    <inertial>
      <mass value="1" />
      <inertia ixx="0.4" ixy="0.0" ixz="0.0" iyy="0.4" iyz="0.0" izz="0.2" />
    </inertial>
  </link>
  <joint name="Joint_3" type="revolute">
    <parent link="Link_2_child_frame" />
    <child link="Link_3" />
    <origin rpy="0 0 0" xyz="0 0.0 0" />
    <axis xyz="0 0 1" />
    <dynamics damping="0.0" friction="0.0" />
    <limit effort="10" lower="-10" upper="10" velocity="10" />
  </joint>
  <link name="Link_3_child_frame">
  </link>
  <joint name="3_child_frame_joint" type="fixed">
    <origin rpy="1.57079632679 0 0" xyz="0  0 0.10915" />
    <parent link="Link_3" />
    <child link="Link_3_child_frame" />
  </joint>
  <material name="mat_4">
    <color rgba="1 1 0 0.7" />
  </material>
  <link name="Link_4">
    <visual>
      <geometry>
        <cylinder length="0.09465" radius="0.05" />
      </geometry>
      <origin rpy="0 0 0" xyz="0  0 0.047325" />
      <material name="mat_4" />
    </visual>
    <collision>
      <geometry>
        <cylinder length="0.09465" radius="0.05" />
      </geometry>
      <origin rpy="0 0 0" xyz="0  0 0.047325" />
    </collision>
    <inertial>
      <mass value="1" />
      <inertia ixx="0.4" ixy="0.0" ixz="0.0" iyy="0.4" iyz="0.0" izz="0.2" />
    </inertial>
  </link>
  <joint name="Joint_4" type="revolute">
    <parent link="Link_3_child_frame" />
    <child link="Link_4" />
    <origin rpy="0 0 0" xyz="0 0.0 0" />
    <axis xyz="0 0 1" />
    <dynamics damping="0.0" friction="0.0" />
    <limit effort="10" lower="-10" upper="10" velocity="10" />
  </joint>
  <link name="Link_4_child_frame">
  </link>
  <joint name="4_child_frame_joint" type="fixed">
    <origin rpy="-1.57079632679 0 0" xyz="0  0 0.09465" />
    <parent link="Link_4" />
    <child link="Link_4_child_frame" />
  </joint>
  <material name="mat_5">
    <color rgba="1 1 1 0.7" />
  </material>
  <link name="Link_5">
    <visual>
      <geometry>
        <cylinder length="0.0823" radius="0.05" />
      </geometry>
      <origin rpy="0 0 0" xyz="0  0 0.04115" />
      <material name="mat_5" />
    </visual>
    <collision>
      <geometry>
        <cylinder length="0.0823" radius="0.05" />
      </geometry>
      <origin rpy="0 0 0" xyz="0  0 0.04115" />
    </collision>
    <inertial>
      <mass value="1" />
      <inertia ixx="0.4" ixy="0.0" ixz="0.0" iyy="0.4" iyz="0.0" izz="0.2" />
    </inertial>
  </link>
  <joint name="Joint_5" type="revolute">
    <parent link="Link_4_child_frame" />
    <child link="Link_5" />
    <origin rpy="0 0 0" xyz="0 0.0 0" />
    <axis xyz="0 0 1" />
    <dynamics damping="0.0" friction="0.0" />
    <limit effort="10" lower="-10" upper="10" velocity="10" />
  </joint>
  <link name="Link_5_child_frame">
  </link>
  <joint name="5_child_frame_joint" type="fixed">
    <origin rpy="0 0 0" xyz="0  0 0.0823" />
    <parent link="Link_5" />
    <child link="Link_5_child_frame" />
  </joint>
</robot>